xTraceback (most recent call last):
  File "/home/acer/environments/test2/bin/celery", line 11, in <module>
    sys.exit(main())
  File "/home/acer/environments/test2/lib/python3.6/site-packages/celery/__main__.py", line 15, in main
    sys.exit(_main())
  File "/home/acer/environments/test2/lib/python3.6/site-packages/celery/bin/celery.py", line 213, in main
    return celery(auto_envvar_prefix="CELERY")
  File "/home/acer/environments/test2/lib/python3.6/site-packages/click/core.py", line 829, in __call__
    return self.main(*args, **kwargs)
  File "/home/acer/environments/test2/lib/python3.6/site-packages/click/core.py", line 782, in main
    rv = self.invoke(ctx)
  File "/home/acer/environments/test2/lib/python3.6/site-packages/click/core.py", line 1259, in invoke
    return _process_result(sub_ctx.command.invoke(sub_ctx))
  File "/home/acer/environments/test2/lib/python3.6/site-packages/click/core.py", line 1066, in invoke
    return ctx.invoke(self.callback, **ctx.params)
  File "/home/acer/environments/test2/lib/python3.6/site-packages/click/core.py", line 610, in invoke
    return callback(*args, **kwargs)
  File "/home/acer/environments/test2/lib/python3.6/site-packages/click/decorators.py", line 21, in new_func
    return f(get_current_context(), *args, **kwargs)
  File "/home/acer/environments/test2/lib/python3.6/site-packages/celery/bin/base.py", line 132, in caller
    return f(ctx, *args, **kwargs)
  File "/home/acer/environments/test2/lib/python3.6/site-packages/celery/bin/worker.py", line 326, in worker
    **kwargs)
  File "/home/acer/environments/test2/lib/python3.6/site-packages/celery/worker/worker.py", line 94, in __init__
    self.app.loader.init_worker()
  File "/home/acer/environments/test2/lib/python3.6/site-packages/celery/loaders/base.py", line 111, in init_worker
    self.import_default_modules()
  File "/home/acer/environments/test2/lib/python3.6/site-packages/celery/loaders/base.py", line 105, in import_default_modules
    raise response
  File "/home/acer/environments/test2/lib/python3.6/site-packages/celery/utils/dispatch/signal.py", line 276, in send
    response = receiver(signal=self, sender=sender, **named)
  File "/home/acer/environments/test2/lib/python3.6/site-packages/celery/fixups/django.py", line 82, in on_import_modules
    self.worker_fixup.validate_models()
  File "/home/acer/environments/test2/lib/python3.6/site-packages/celery/fixups/django.py", line 121, in validate_models
    run_checks()
  File "/home/acer/environments/test2/lib/python3.6/site-packages/django/core/checks/registry.py", line 76, in run_checks
    new_errors = check(app_configs=app_configs, databases=databases)
  File "/home/acer/environments/test2/lib/python3.6/site-packages/django/core/checks/urls.py", line 13, in check_url_config
    return check_resolver(resolver)
  File "/home/acer/environments/test2/lib/python3.6/site-packages/django/core/checks/urls.py", line 23, in check_resolver
    return check_method()
  File "/home/acer/environments/test2/lib/python3.6/site-packages/django/urls/resolvers.py", line 412, in check
    for pattern in self.url_patterns:
  File "/home/acer/environments/test2/lib/python3.6/site-packages/django/utils/functional.py", line 48, in __get__
    res = instance.__dict__[self.name] = self.func(instance)
  File "/home/acer/environments/test2/lib/python3.6/site-packages/django/urls/resolvers.py", line 598, in url_patterns
    patterns = getattr(self.urlconf_module, "urlpatterns", self.urlconf_module)
  File "/home/acer/environments/test2/lib/python3.6/site-packages/django/utils/functional.py", line 48, in __get__
    res = instance.__dict__[self.name] = self.func(instance)
  File "/home/acer/environments/test2/lib/python3.6/site-packages/django/urls/resolvers.py", line 591, in urlconf_module
    return import_module(self.urlconf_name)
  File "/usr/lib/python3.6/importlib/__init__.py", line 126, in import_module
    return _bootstrap._gcd_import(name[level:], package, level)
  File "<frozen importlib._bootstrap>", line 994, in _gcd_import
  File "<frozen importlib._bootstrap>", line 971, in _find_and_load
  File "<frozen importlib._bootstrap>", line 955, in _find_and_load_unlocked
  File "<frozen importlib._bootstrap>", line 665, in _load_unlocked
  File "<frozen importlib._bootstrap_external>", line 678, in exec_module
  File "<frozen importlib._bootstrap>", line 219, in _call_with_frames_removed
  File "/home/acer/projects/tracker/tracker/urls.py", line 24, in <module>
    path('core/', include('core.urls')),
  File "/home/acer/environments/test2/lib/python3.6/site-packages/django/urls/conf.py", line 34, in include
    urlconf_module = import_module(urlconf_module)
  File "/usr/lib/python3.6/importlib/__init__.py", line 126, in import_module
    return _bootstrap._gcd_import(name[level:], package, level)
  File "<frozen importlib._bootstrap>", line 994, in _gcd_import
  File "<frozen importlib._bootstrap>", line 971, in _find_and_load
  File "<frozen importlib._bootstrap>", line 955, in _find_and_load_unlocked
  File "<frozen importlib._bootstrap>", line 665, in _load_unlocked
  File "<frozen importlib._bootstrap_external>", line 678, in exec_module
  File "<frozen importlib._bootstrap>", line 219, in _call_with_frames_removed
  File "/home/acer/projects/tracker/core/urls.py", line 2, in <module>
    from core import views
  File "/home/acer/projects/tracker/core/views.py", line 14, in <module>
    from tasks import send_email
ModuleNotFoundError: No module named 'tasks'
Traceback (most recent call last):
  File "/home/acer/environments/test2/bin/celery", line 11, in <module>
    sys.exit(main())
  File "/home/acer/environments/test2/lib/python3.6/site-packages/celery/__main__.py", line 15, in main
    sys.exit(_main())
  File "/home/acer/environments/test2/lib/python3.6/site-packages/celery/bin/celery.py", line 213, in main
    return celery(auto_envvar_prefix="CELERY")
  File "/home/acer/environments/test2/lib/python3.6/site-packages/click/core.py", line 829, in __call__
    return self.main(*args, **kwargs)
  File "/home/acer/environments/test2/lib/python3.6/site-packages/click/core.py", line 782, in main
    rv = self.invoke(ctx)
  File "/home/acer/environments/test2/lib/python3.6/site-packages/click/core.py", line 1259, in invoke
    return _process_result(sub_ctx.command.invoke(sub_ctx))
  File "/home/acer/environments/test2/lib/python3.6/site-packages/click/core.py", line 1066, in invoke
    return ctx.invoke(self.callback, **ctx.params)
  File "/home/acer/environments/test2/lib/python3.6/site-packages/click/core.py", line 610, in invoke
    return callback(*args, **kwargs)
  File "/home/acer/environments/test2/lib/python3.6/site-packages/click/decorators.py", line 21, in new_func
    return f(get_current_context(), *args, **kwargs)
  File "/home/acer/environments/test2/lib/python3.6/site-packages/celery/bin/base.py", line 132, in caller
    return f(ctx, *args, **kwargs)
  File "/home/acer/environments/test2/lib/python3.6/site-packages/celery/bin/worker.py", line 326, in worker
    **kwargs)
  File "/home/acer/environments/test2/lib/python3.6/site-packages/celery/worker/worker.py", line 94, in __init__
    self.app.loader.init_worker()
  File "/home/acer/environments/test2/lib/python3.6/site-packages/celery/loaders/base.py", line 111, in init_worker
    self.import_default_modules()
  File "/home/acer/environments/test2/lib/python3.6/site-packages/celery/loaders/base.py", line 105, in import_default_modules
    raise response
  File "/home/acer/environments/test2/lib/python3.6/site-packages/celery/utils/dispatch/signal.py", line 276, in send
    response = receiver(signal=self, sender=sender, **named)
  File "/home/acer/environments/test2/lib/python3.6/site-packages/celery/fixups/django.py", line 82, in on_import_modules
    self.worker_fixup.validate_models()
  File "/home/acer/environments/test2/lib/python3.6/site-packages/celery/fixups/django.py", line 121, in validate_models
    run_checks()
  File "/home/acer/environments/test2/lib/python3.6/site-packages/django/core/checks/registry.py", line 76, in run_checks
    new_errors = check(app_configs=app_configs, databases=databases)
  File "/home/acer/environments/test2/lib/python3.6/site-packages/django/core/checks/urls.py", line 13, in check_url_config
    return check_resolver(resolver)
  File "/home/acer/environments/test2/lib/python3.6/site-packages/django/core/checks/urls.py", line 23, in check_resolver
    return check_method()
  File "/home/acer/environments/test2/lib/python3.6/site-packages/django/urls/resolvers.py", line 412, in check
    for pattern in self.url_patterns:
  File "/home/acer/environments/test2/lib/python3.6/site-packages/django/utils/functional.py", line 48, in __get__
    res = instance.__dict__[self.name] = self.func(instance)
  File "/home/acer/environments/test2/lib/python3.6/site-packages/django/urls/resolvers.py", line 598, in url_patterns
    patterns = getattr(self.urlconf_module, "urlpatterns", self.urlconf_module)
  File "/home/acer/environments/test2/lib/python3.6/site-packages/django/utils/functional.py", line 48, in __get__
    res = instance.__dict__[self.name] = self.func(instance)
  File "/home/acer/environments/test2/lib/python3.6/site-packages/django/urls/resolvers.py", line 591, in urlconf_module
    return import_module(self.urlconf_name)
  File "/usr/lib/python3.6/importlib/__init__.py", line 126, in import_module
    return _bootstrap._gcd_import(name[level:], package, level)
  File "<frozen importlib._bootstrap>", line 994, in _gcd_import
  File "<frozen importlib._bootstrap>", line 971, in _find_and_load
  File "<frozen importlib._bootstrap>", line 955, in _find_and_load_unlocked
  File "<frozen importlib._bootstrap>", line 665, in _load_unlocked
  File "<frozen importlib._bootstrap_external>", line 678, in exec_module
  File "<frozen importlib._bootstrap>", line 219, in _call_with_frames_removed
  File "/home/acer/projects/tracker/tracker/urls.py", line 24, in <module>
    path('core/', include('core.urls')),
  File "/home/acer/environments/test2/lib/python3.6/site-packages/django/urls/conf.py", line 34, in include
    urlconf_module = import_module(urlconf_module)
  File "/usr/lib/python3.6/importlib/__init__.py", line 126, in import_module
    return _bootstrap._gcd_import(name[level:], package, level)
  File "<frozen importlib._bootstrap>", line 994, in _gcd_import
  File "<frozen importlib._bootstrap>", line 971, in _find_and_load
  File "<frozen importlib._bootstrap>", line 955, in _find_and_load_unlocked
  File "<frozen importlib._bootstrap>", line 665, in _load_unlocked
  File "<frozen importlib._bootstrap_external>", line 678, in exec_module
  File "<frozen importlib._bootstrap>", line 219, in _call_with_frames_removed
  File "/home/acer/projects/tracker/core/urls.py", line 2, in <module>
    from core import views
  File "/home/acer/projects/tracker/core/views.py", line 14, in <module>
    from tasks import send_email
ModuleNotFoundError: No module named 'tasks'
Traceback (most recent call last):
  File "/home/acer/environments/test2/bin/celery", line 11, in <module>
    sys.exit(main())
  File "/home/acer/environments/test2/lib/python3.6/site-packages/celery/__main__.py", line 15, in main
    sys.exit(_main())
  File "/home/acer/environments/test2/lib/python3.6/site-packages/celery/bin/celery.py", line 213, in main
    return celery(auto_envvar_prefix="CELERY")
  File "/home/acer/environments/test2/lib/python3.6/site-packages/click/core.py", line 829, in __call__
    return self.main(*args, **kwargs)
  File "/home/acer/environments/test2/lib/python3.6/site-packages/click/core.py", line 782, in main
    rv = self.invoke(ctx)
  File "/home/acer/environments/test2/lib/python3.6/site-packages/click/core.py", line 1259, in invoke
    return _process_result(sub_ctx.command.invoke(sub_ctx))
  File "/home/acer/environments/test2/lib/python3.6/site-packages/click/core.py", line 1066, in invoke
    return ctx.invoke(self.callback, **ctx.params)
  File "/home/acer/environments/test2/lib/python3.6/site-packages/click/core.py", line 610, in invoke
    return callback(*args, **kwargs)
  File "/home/acer/environments/test2/lib/python3.6/site-packages/click/decorators.py", line 21, in new_func
    return f(get_current_context(), *args, **kwargs)
  File "/home/acer/environments/test2/lib/python3.6/site-packages/celery/bin/base.py", line 132, in caller
    return f(ctx, *args, **kwargs)
  File "/home/acer/environments/test2/lib/python3.6/site-packages/celery/bin/worker.py", line 326, in worker
    **kwargs)
  File "/home/acer/environments/test2/lib/python3.6/site-packages/celery/worker/worker.py", line 94, in __init__
    self.app.loader.init_worker()
  File "/home/acer/environments/test2/lib/python3.6/site-packages/celery/loaders/base.py", line 111, in init_worker
    self.import_default_modules()
  File "/home/acer/environments/test2/lib/python3.6/site-packages/celery/loaders/base.py", line 105, in import_default_modules
    raise response
  File "/home/acer/environments/test2/lib/python3.6/site-packages/celery/utils/dispatch/signal.py", line 276, in send
    response = receiver(signal=self, sender=sender, **named)
  File "/home/acer/environments/test2/lib/python3.6/site-packages/celery/fixups/django.py", line 82, in on_import_modules
    self.worker_fixup.validate_models()
  File "/home/acer/environments/test2/lib/python3.6/site-packages/celery/fixups/django.py", line 121, in validate_models
    run_checks()
  File "/home/acer/environments/test2/lib/python3.6/site-packages/django/core/checks/registry.py", line 76, in run_checks
    new_errors = check(app_configs=app_configs, databases=databases)
  File "/home/acer/environments/test2/lib/python3.6/site-packages/django/core/checks/urls.py", line 13, in check_url_config
    return check_resolver(resolver)
  File "/home/acer/environments/test2/lib/python3.6/site-packages/django/core/checks/urls.py", line 23, in check_resolver
    return check_method()
  File "/home/acer/environments/test2/lib/python3.6/site-packages/django/urls/resolvers.py", line 412, in check
    for pattern in self.url_patterns:
  File "/home/acer/environments/test2/lib/python3.6/site-packages/django/utils/functional.py", line 48, in __get__
    res = instance.__dict__[self.name] = self.func(instance)
  File "/home/acer/environments/test2/lib/python3.6/site-packages/django/urls/resolvers.py", line 598, in url_patterns
    patterns = getattr(self.urlconf_module, "urlpatterns", self.urlconf_module)
  File "/home/acer/environments/test2/lib/python3.6/site-packages/django/utils/functional.py", line 48, in __get__
    res = instance.__dict__[self.name] = self.func(instance)
  File "/home/acer/environments/test2/lib/python3.6/site-packages/django/urls/resolvers.py", line 591, in urlconf_module
    return import_module(self.urlconf_name)
  File "/usr/lib/python3.6/importlib/__init__.py", line 126, in import_module
    return _bootstrap._gcd_import(name[level:], package, level)
  File "<frozen importlib._bootstrap>", line 994, in _gcd_import
  File "<frozen importlib._bootstrap>", line 971, in _find_and_load
  File "<frozen importlib._bootstrap>", line 955, in _find_and_load_unlocked
  File "<frozen importlib._bootstrap>", line 665, in _load_unlocked
  File "<frozen importlib._bootstrap_external>", line 678, in exec_module
  File "<frozen importlib._bootstrap>", line 219, in _call_with_frames_removed
  File "/home/acer/projects/tracker/tracker/urls.py", line 24, in <module>
    path('core/', include('core.urls')),
  File "/home/acer/environments/test2/lib/python3.6/site-packages/django/urls/conf.py", line 34, in include
    urlconf_module = import_module(urlconf_module)
  File "/usr/lib/python3.6/importlib/__init__.py", line 126, in import_module
    return _bootstrap._gcd_import(name[level:], package, level)
  File "<frozen importlib._bootstrap>", line 994, in _gcd_import
  File "<frozen importlib._bootstrap>", line 971, in _find_and_load
  File "<frozen importlib._bootstrap>", line 955, in _find_and_load_unlocked
  File "<frozen importlib._bootstrap>", line 665, in _load_unlocked
  File "<frozen importlib._bootstrap_external>", line 678, in exec_module
  File "<frozen importlib._bootstrap>", line 219, in _call_with_frames_removed
  File "/home/acer/projects/tracker/core/urls.py", line 2, in <module>
    from core import views
  File "/home/acer/projects/tracker/core/views.py", line 14, in <module>
    from tasks import send_email
ModuleNotFoundError: No module named 'tasks'
Traceback (most recent call last):
  File "/home/acer/environments/test2/bin/celery", line 11, in <module>
    sys.exit(main())
  File "/home/acer/environments/test2/lib/python3.6/site-packages/celery/__main__.py", line 15, in main
    sys.exit(_main())
  File "/home/acer/environments/test2/lib/python3.6/site-packages/celery/bin/celery.py", line 213, in main
    return celery(auto_envvar_prefix="CELERY")
  File "/home/acer/environments/test2/lib/python3.6/site-packages/click/core.py", line 829, in __call__
    return self.main(*args, **kwargs)
  File "/home/acer/environments/test2/lib/python3.6/site-packages/click/core.py", line 782, in main
    rv = self.invoke(ctx)
  File "/home/acer/environments/test2/lib/python3.6/site-packages/click/core.py", line 1259, in invoke
    return _process_result(sub_ctx.command.invoke(sub_ctx))
  File "/home/acer/environments/test2/lib/python3.6/site-packages/click/core.py", line 1066, in invoke
    return ctx.invoke(self.callback, **ctx.params)
  File "/home/acer/environments/test2/lib/python3.6/site-packages/click/core.py", line 610, in invoke
    return callback(*args, **kwargs)
  File "/home/acer/environments/test2/lib/python3.6/site-packages/click/decorators.py", line 21, in new_func
    return f(get_current_context(), *args, **kwargs)
  File "/home/acer/environments/test2/lib/python3.6/site-packages/celery/bin/base.py", line 132, in caller
    return f(ctx, *args, **kwargs)
  File "/home/acer/environments/test2/lib/python3.6/site-packages/celery/bin/worker.py", line 326, in worker
    **kwargs)
  File "/home/acer/environments/test2/lib/python3.6/site-packages/celery/worker/worker.py", line 94, in __init__
    self.app.loader.init_worker()
  File "/home/acer/environments/test2/lib/python3.6/site-packages/celery/loaders/base.py", line 111, in init_worker
    self.import_default_modules()
  File "/home/acer/environments/test2/lib/python3.6/site-packages/celery/loaders/base.py", line 105, in import_default_modules
    raise response
  File "/home/acer/environments/test2/lib/python3.6/site-packages/celery/utils/dispatch/signal.py", line 276, in send
    response = receiver(signal=self, sender=sender, **named)
  File "/home/acer/environments/test2/lib/python3.6/site-packages/celery/fixups/django.py", line 82, in on_import_modules
    self.worker_fixup.validate_models()
  File "/home/acer/environments/test2/lib/python3.6/site-packages/celery/fixups/django.py", line 121, in validate_models
    run_checks()
  File "/home/acer/environments/test2/lib/python3.6/site-packages/django/core/checks/registry.py", line 76, in run_checks
    new_errors = check(app_configs=app_configs, databases=databases)
  File "/home/acer/environments/test2/lib/python3.6/site-packages/django/core/checks/urls.py", line 13, in check_url_config
    return check_resolver(resolver)
  File "/home/acer/environments/test2/lib/python3.6/site-packages/django/core/checks/urls.py", line 23, in check_resolver
    return check_method()
  File "/home/acer/environments/test2/lib/python3.6/site-packages/django/urls/resolvers.py", line 412, in check
    for pattern in self.url_patterns:
  File "/home/acer/environments/test2/lib/python3.6/site-packages/django/utils/functional.py", line 48, in __get__
    res = instance.__dict__[self.name] = self.func(instance)
  File "/home/acer/environments/test2/lib/python3.6/site-packages/django/urls/resolvers.py", line 598, in url_patterns
    patterns = getattr(self.urlconf_module, "urlpatterns", self.urlconf_module)
  File "/home/acer/environments/test2/lib/python3.6/site-packages/django/utils/functional.py", line 48, in __get__
    res = instance.__dict__[self.name] = self.func(instance)
  File "/home/acer/environments/test2/lib/python3.6/site-packages/django/urls/resolvers.py", line 591, in urlconf_module
    return import_module(self.urlconf_name)
  File "/usr/lib/python3.6/importlib/__init__.py", line 126, in import_module
    return _bootstrap._gcd_import(name[level:], package, level)
  File "<frozen importlib._bootstrap>", line 994, in _gcd_import
  File "<frozen importlib._bootstrap>", line 971, in _find_and_load
  File "<frozen importlib._bootstrap>", line 955, in _find_and_load_unlocked
  File "<frozen importlib._bootstrap>", line 665, in _load_unlocked
  File "<frozen importlib._bootstrap_external>", line 678, in exec_module
  File "<frozen importlib._bootstrap>", line 219, in _call_with_frames_removed
  File "/home/acer/projects/tracker/tracker/urls.py", line 24, in <module>
    path('core/', include('core.urls')),
  File "/home/acer/environments/test2/lib/python3.6/site-packages/django/urls/conf.py", line 34, in include
    urlconf_module = import_module(urlconf_module)
  File "/usr/lib/python3.6/importlib/__init__.py", line 126, in import_module
    return _bootstrap._gcd_import(name[level:], package, level)
  File "<frozen importlib._bootstrap>", line 994, in _gcd_import
  File "<frozen importlib._bootstrap>", line 971, in _find_and_load
  File "<frozen importlib._bootstrap>", line 955, in _find_and_load_unlocked
  File "<frozen importlib._bootstrap>", line 665, in _load_unlocked
  File "<frozen importlib._bootstrap_external>", line 678, in exec_module
  File "<frozen importlib._bootstrap>", line 219, in _call_with_frames_removed
  File "/home/acer/projects/tracker/core/urls.py", line 2, in <module>
    from core import views
  File "/home/acer/projects/tracker/core/views.py", line 14, in <module>
    from tasks import send_email
ModuleNotFoundError: No module named 'tasks'
Traceback (most recent call last):
  File "/home/acer/environments/test2/bin/celery", line 11, in <module>
    sys.exit(main())
  File "/home/acer/environments/test2/lib/python3.6/site-packages/celery/__main__.py", line 15, in main
    sys.exit(_main())
  File "/home/acer/environments/test2/lib/python3.6/site-packages/celery/bin/celery.py", line 213, in main
    return celery(auto_envvar_prefix="CELERY")
  File "/home/acer/environments/test2/lib/python3.6/site-packages/click/core.py", line 829, in __call__
    return self.main(*args, **kwargs)
  File "/home/acer/environments/test2/lib/python3.6/site-packages/click/core.py", line 782, in main
    rv = self.invoke(ctx)
  File "/home/acer/environments/test2/lib/python3.6/site-packages/click/core.py", line 1259, in invoke
    return _process_result(sub_ctx.command.invoke(sub_ctx))
  File "/home/acer/environments/test2/lib/python3.6/site-packages/click/core.py", line 1066, in invoke
    return ctx.invoke(self.callback, **ctx.params)
  File "/home/acer/environments/test2/lib/python3.6/site-packages/click/core.py", line 610, in invoke
    return callback(*args, **kwargs)
  File "/home/acer/environments/test2/lib/python3.6/site-packages/click/decorators.py", line 21, in new_func
    return f(get_current_context(), *args, **kwargs)
  File "/home/acer/environments/test2/lib/python3.6/site-packages/celery/bin/base.py", line 132, in caller
    return f(ctx, *args, **kwargs)
  File "/home/acer/environments/test2/lib/python3.6/site-packages/celery/bin/worker.py", line 326, in worker
    **kwargs)
  File "/home/acer/environments/test2/lib/python3.6/site-packages/celery/worker/worker.py", line 94, in __init__
    self.app.loader.init_worker()
  File "/home/acer/environments/test2/lib/python3.6/site-packages/celery/loaders/base.py", line 111, in init_worker
    self.import_default_modules()
  File "/home/acer/environments/test2/lib/python3.6/site-packages/celery/loaders/base.py", line 105, in import_default_modules
    raise response
  File "/home/acer/environments/test2/lib/python3.6/site-packages/celery/utils/dispatch/signal.py", line 276, in send
    response = receiver(signal=self, sender=sender, **named)
  File "/home/acer/environments/test2/lib/python3.6/site-packages/celery/fixups/django.py", line 82, in on_import_modules
    self.worker_fixup.validate_models()
  File "/home/acer/environments/test2/lib/python3.6/site-packages/celery/fixups/django.py", line 121, in validate_models
    run_checks()
  File "/home/acer/environments/test2/lib/python3.6/site-packages/django/core/checks/registry.py", line 76, in run_checks
    new_errors = check(app_configs=app_configs, databases=databases)
  File "/home/acer/environments/test2/lib/python3.6/site-packages/django/core/checks/urls.py", line 13, in check_url_config
    return check_resolver(resolver)
  File "/home/acer/environments/test2/lib/python3.6/site-packages/django/core/checks/urls.py", line 23, in check_resolver
    return check_method()
  File "/home/acer/environments/test2/lib/python3.6/site-packages/django/urls/resolvers.py", line 412, in check
    for pattern in self.url_patterns:
  File "/home/acer/environments/test2/lib/python3.6/site-packages/django/utils/functional.py", line 48, in __get__
    res = instance.__dict__[self.name] = self.func(instance)
  File "/home/acer/environments/test2/lib/python3.6/site-packages/django/urls/resolvers.py", line 598, in url_patterns
    patterns = getattr(self.urlconf_module, "urlpatterns", self.urlconf_module)
  File "/home/acer/environments/test2/lib/python3.6/site-packages/django/utils/functional.py", line 48, in __get__
    res = instance.__dict__[self.name] = self.func(instance)
  File "/home/acer/environments/test2/lib/python3.6/site-packages/django/urls/resolvers.py", line 591, in urlconf_module
    return import_module(self.urlconf_name)
  File "/usr/lib/python3.6/importlib/__init__.py", line 126, in import_module
    return _bootstrap._gcd_import(name[level:], package, level)
  File "<frozen importlib._bootstrap>", line 994, in _gcd_import
  File "<frozen importlib._bootstrap>", line 971, in _find_and_load
  File "<frozen importlib._bootstrap>", line 955, in _find_and_load_unlocked
  File "<frozen importlib._bootstrap>", line 665, in _load_unlocked
  File "<frozen importlib._bootstrap_external>", line 678, in exec_module
  File "<frozen importlib._bootstrap>", line 219, in _call_with_frames_removed
  File "/home/acer/projects/tracker/tracker/urls.py", line 24, in <module>
    path('core/', include('core.urls')),
  File "/home/acer/environments/test2/lib/python3.6/site-packages/django/urls/conf.py", line 34, in include
    urlconf_module = import_module(urlconf_module)
  File "/usr/lib/python3.6/importlib/__init__.py", line 126, in import_module
    return _bootstrap._gcd_import(name[level:], package, level)
  File "<frozen importlib._bootstrap>", line 994, in _gcd_import
  File "<frozen importlib._bootstrap>", line 971, in _find_and_load
  File "<frozen importlib._bootstrap>", line 955, in _find_and_load_unlocked
  File "<frozen importlib._bootstrap>", line 665, in _load_unlocked
  File "<frozen importlib._bootstrap_external>", line 678, in exec_module
  File "<frozen importlib._bootstrap>", line 219, in _call_with_frames_removed
  File "/home/acer/projects/tracker/core/urls.py", line 2, in <module>
    from core import views
  File "/home/acer/projects/tracker/core/views.py", line 14, in <module>
    from core.tasks import send_email
  File "/home/acer/projects/tracker/core/tasks.py", line 9
    send_mail(obj.id, constants.UPDATE_MESSAGE, settings.EMAIL_HOST_USER, to_users)
                                                                                  ^
TabError: inconsistent use of tabs and spaces in indentation
Traceback (most recent call last):
  File "/home/acer/environments/test2/bin/celery", line 11, in <module>
    sys.exit(main())
  File "/home/acer/environments/test2/lib/python3.6/site-packages/celery/__main__.py", line 15, in main
    sys.exit(_main())
  File "/home/acer/environments/test2/lib/python3.6/site-packages/celery/bin/celery.py", line 213, in main
    return celery(auto_envvar_prefix="CELERY")
  File "/home/acer/environments/test2/lib/python3.6/site-packages/click/core.py", line 829, in __call__
    return self.main(*args, **kwargs)
  File "/home/acer/environments/test2/lib/python3.6/site-packages/click/core.py", line 782, in main
    rv = self.invoke(ctx)
  File "/home/acer/environments/test2/lib/python3.6/site-packages/click/core.py", line 1259, in invoke
    return _process_result(sub_ctx.command.invoke(sub_ctx))
  File "/home/acer/environments/test2/lib/python3.6/site-packages/click/core.py", line 1066, in invoke
    return ctx.invoke(self.callback, **ctx.params)
  File "/home/acer/environments/test2/lib/python3.6/site-packages/click/core.py", line 610, in invoke
    return callback(*args, **kwargs)
  File "/home/acer/environments/test2/lib/python3.6/site-packages/click/decorators.py", line 21, in new_func
    return f(get_current_context(), *args, **kwargs)
  File "/home/acer/environments/test2/lib/python3.6/site-packages/celery/bin/base.py", line 132, in caller
    return f(ctx, *args, **kwargs)
  File "/home/acer/environments/test2/lib/python3.6/site-packages/celery/bin/worker.py", line 326, in worker
    **kwargs)
  File "/home/acer/environments/test2/lib/python3.6/site-packages/celery/worker/worker.py", line 94, in __init__
    self.app.loader.init_worker()
  File "/home/acer/environments/test2/lib/python3.6/site-packages/celery/loaders/base.py", line 111, in init_worker
    self.import_default_modules()
  File "/home/acer/environments/test2/lib/python3.6/site-packages/celery/loaders/base.py", line 105, in import_default_modules
    raise response
  File "/home/acer/environments/test2/lib/python3.6/site-packages/celery/utils/dispatch/signal.py", line 276, in send
    response = receiver(signal=self, sender=sender, **named)
  File "/home/acer/environments/test2/lib/python3.6/site-packages/celery/fixups/django.py", line 82, in on_import_modules
    self.worker_fixup.validate_models()
  File "/home/acer/environments/test2/lib/python3.6/site-packages/celery/fixups/django.py", line 121, in validate_models
    run_checks()
  File "/home/acer/environments/test2/lib/python3.6/site-packages/django/core/checks/registry.py", line 76, in run_checks
    new_errors = check(app_configs=app_configs, databases=databases)
  File "/home/acer/environments/test2/lib/python3.6/site-packages/django/core/checks/urls.py", line 13, in check_url_config
    return check_resolver(resolver)
  File "/home/acer/environments/test2/lib/python3.6/site-packages/django/core/checks/urls.py", line 23, in check_resolver
    return check_method()
  File "/home/acer/environments/test2/lib/python3.6/site-packages/django/urls/resolvers.py", line 412, in check
    for pattern in self.url_patterns:
  File "/home/acer/environments/test2/lib/python3.6/site-packages/django/utils/functional.py", line 48, in __get__
    res = instance.__dict__[self.name] = self.func(instance)
  File "/home/acer/environments/test2/lib/python3.6/site-packages/django/urls/resolvers.py", line 598, in url_patterns
    patterns = getattr(self.urlconf_module, "urlpatterns", self.urlconf_module)
  File "/home/acer/environments/test2/lib/python3.6/site-packages/django/utils/functional.py", line 48, in __get__
    res = instance.__dict__[self.name] = self.func(instance)
  File "/home/acer/environments/test2/lib/python3.6/site-packages/django/urls/resolvers.py", line 591, in urlconf_module
    return import_module(self.urlconf_name)
  File "/usr/lib/python3.6/importlib/__init__.py", line 126, in import_module
    return _bootstrap._gcd_import(name[level:], package, level)
  File "<frozen importlib._bootstrap>", line 994, in _gcd_import
  File "<frozen importlib._bootstrap>", line 971, in _find_and_load
  File "<frozen importlib._bootstrap>", line 955, in _find_and_load_unlocked
  File "<frozen importlib._bootstrap>", line 665, in _load_unlocked
  File "<frozen importlib._bootstrap_external>", line 678, in exec_module
  File "<frozen importlib._bootstrap>", line 219, in _call_with_frames_removed
  File "/home/acer/projects/tracker/tracker/urls.py", line 24, in <module>
    path('core/', include('core.urls')),
  File "/home/acer/environments/test2/lib/python3.6/site-packages/django/urls/conf.py", line 34, in include
    urlconf_module = import_module(urlconf_module)
  File "/usr/lib/python3.6/importlib/__init__.py", line 126, in import_module
    return _bootstrap._gcd_import(name[level:], package, level)
  File "<frozen importlib._bootstrap>", line 994, in _gcd_import
  File "<frozen importlib._bootstrap>", line 971, in _find_and_load
  File "<frozen importlib._bootstrap>", line 955, in _find_and_load_unlocked
  File "<frozen importlib._bootstrap>", line 665, in _load_unlocked
  File "<frozen importlib._bootstrap_external>", line 678, in exec_module
  File "<frozen importlib._bootstrap>", line 219, in _call_with_frames_removed
  File "/home/acer/projects/tracker/core/urls.py", line 2, in <module>
    from core import views
  File "/home/acer/projects/tracker/core/views.py", line 14, in <module>
    from core.tasks import send_email
  File "/home/acer/projects/tracker/core/tasks.py", line 9
    send_mail(obj.id, constants.UPDATE_MESSAGE, settings.EMAIL_HOST_USER, to_users)
                                                                                  ^
TabError: inconsistent use of tabs and spaces in indentation
Traceback (most recent call last):
  File "/home/acer/environments/test2/bin/celery", line 11, in <module>
    sys.exit(main())
  File "/home/acer/environments/test2/lib/python3.6/site-packages/celery/__main__.py", line 15, in main
    sys.exit(_main())
  File "/home/acer/environments/test2/lib/python3.6/site-packages/celery/bin/celery.py", line 213, in main
    return celery(auto_envvar_prefix="CELERY")
  File "/home/acer/environments/test2/lib/python3.6/site-packages/click/core.py", line 829, in __call__
    return self.main(*args, **kwargs)
  File "/home/acer/environments/test2/lib/python3.6/site-packages/click/core.py", line 782, in main
    rv = self.invoke(ctx)
  File "/home/acer/environments/test2/lib/python3.6/site-packages/click/core.py", line 1259, in invoke
    return _process_result(sub_ctx.command.invoke(sub_ctx))
  File "/home/acer/environments/test2/lib/python3.6/site-packages/click/core.py", line 1066, in invoke
    return ctx.invoke(self.callback, **ctx.params)
  File "/home/acer/environments/test2/lib/python3.6/site-packages/click/core.py", line 610, in invoke
    return callback(*args, **kwargs)
  File "/home/acer/environments/test2/lib/python3.6/site-packages/click/decorators.py", line 21, in new_func
    return f(get_current_context(), *args, **kwargs)
  File "/home/acer/environments/test2/lib/python3.6/site-packages/celery/bin/base.py", line 132, in caller
    return f(ctx, *args, **kwargs)
  File "/home/acer/environments/test2/lib/python3.6/site-packages/celery/bin/worker.py", line 326, in worker
    **kwargs)
  File "/home/acer/environments/test2/lib/python3.6/site-packages/celery/worker/worker.py", line 94, in __init__
    self.app.loader.init_worker()
  File "/home/acer/environments/test2/lib/python3.6/site-packages/celery/loaders/base.py", line 111, in init_worker
    self.import_default_modules()
  File "/home/acer/environments/test2/lib/python3.6/site-packages/celery/loaders/base.py", line 105, in import_default_modules
    raise response
  File "/home/acer/environments/test2/lib/python3.6/site-packages/celery/utils/dispatch/signal.py", line 276, in send
    response = receiver(signal=self, sender=sender, **named)
  File "/home/acer/environments/test2/lib/python3.6/site-packages/celery/fixups/django.py", line 82, in on_import_modules
    self.worker_fixup.validate_models()
  File "/home/acer/environments/test2/lib/python3.6/site-packages/celery/fixups/django.py", line 121, in validate_models
    run_checks()
  File "/home/acer/environments/test2/lib/python3.6/site-packages/django/core/checks/registry.py", line 76, in run_checks
    new_errors = check(app_configs=app_configs, databases=databases)
  File "/home/acer/environments/test2/lib/python3.6/site-packages/django/core/checks/urls.py", line 13, in check_url_config
    return check_resolver(resolver)
  File "/home/acer/environments/test2/lib/python3.6/site-packages/django/core/checks/urls.py", line 23, in check_resolver
    return check_method()
  File "/home/acer/environments/test2/lib/python3.6/site-packages/django/urls/resolvers.py", line 412, in check
    for pattern in self.url_patterns:
  File "/home/acer/environments/test2/lib/python3.6/site-packages/django/utils/functional.py", line 48, in __get__
    res = instance.__dict__[self.name] = self.func(instance)
  File "/home/acer/environments/test2/lib/python3.6/site-packages/django/urls/resolvers.py", line 598, in url_patterns
    patterns = getattr(self.urlconf_module, "urlpatterns", self.urlconf_module)
  File "/home/acer/environments/test2/lib/python3.6/site-packages/django/utils/functional.py", line 48, in __get__
    res = instance.__dict__[self.name] = self.func(instance)
  File "/home/acer/environments/test2/lib/python3.6/site-packages/django/urls/resolvers.py", line 591, in urlconf_module
    return import_module(self.urlconf_name)
  File "/usr/lib/python3.6/importlib/__init__.py", line 126, in import_module
    return _bootstrap._gcd_import(name[level:], package, level)
  File "<frozen importlib._bootstrap>", line 994, in _gcd_import
  File "<frozen importlib._bootstrap>", line 971, in _find_and_load
  File "<frozen importlib._bootstrap>", line 955, in _find_and_load_unlocked
  File "<frozen importlib._bootstrap>", line 665, in _load_unlocked
  File "<frozen importlib._bootstrap_external>", line 678, in exec_module
  File "<frozen importlib._bootstrap>", line 219, in _call_with_frames_removed
  File "/home/acer/projects/tracker/tracker/urls.py", line 24, in <module>
    path('core/', include('core.urls')),
  File "/home/acer/environments/test2/lib/python3.6/site-packages/django/urls/conf.py", line 34, in include
    urlconf_module = import_module(urlconf_module)
  File "/usr/lib/python3.6/importlib/__init__.py", line 126, in import_module
    return _bootstrap._gcd_import(name[level:], package, level)
  File "<frozen importlib._bootstrap>", line 994, in _gcd_import
  File "<frozen importlib._bootstrap>", line 971, in _find_and_load
  File "<frozen importlib._bootstrap>", line 955, in _find_and_load_unlocked
  File "<frozen importlib._bootstrap>", line 665, in _load_unlocked
  File "<frozen importlib._bootstrap_external>", line 678, in exec_module
  File "<frozen importlib._bootstrap>", line 219, in _call_with_frames_removed
  File "/home/acer/projects/tracker/core/urls.py", line 2, in <module>
    from core import views
  File "/home/acer/projects/tracker/core/views.py", line 14, in <module>
    from core.tasks import send_email
  File "/home/acer/projects/tracker/core/tasks.py", line 9
    send_mail(obj.id, constants.UPDATE_MESSAGE, settings.EMAIL_HOST_USER, to_users)
                                                                                  ^
TabError: inconsistent use of tabs and spaces in indentation
Traceback (most recent call last):
  File "/home/acer/environments/test2/bin/celery", line 11, in <module>
    sys.exit(main())
  File "/home/acer/environments/test2/lib/python3.6/site-packages/celery/__main__.py", line 15, in main
    sys.exit(_main())
  File "/home/acer/environments/test2/lib/python3.6/site-packages/celery/bin/celery.py", line 213, in main
    return celery(auto_envvar_prefix="CELERY")
  File "/home/acer/environments/test2/lib/python3.6/site-packages/click/core.py", line 829, in __call__
    return self.main(*args, **kwargs)
  File "/home/acer/environments/test2/lib/python3.6/site-packages/click/core.py", line 782, in main
    rv = self.invoke(ctx)
  File "/home/acer/environments/test2/lib/python3.6/site-packages/click/core.py", line 1259, in invoke
    return _process_result(sub_ctx.command.invoke(sub_ctx))
  File "/home/acer/environments/test2/lib/python3.6/site-packages/click/core.py", line 1066, in invoke
    return ctx.invoke(self.callback, **ctx.params)
  File "/home/acer/environments/test2/lib/python3.6/site-packages/click/core.py", line 610, in invoke
    return callback(*args, **kwargs)
  File "/home/acer/environments/test2/lib/python3.6/site-packages/click/decorators.py", line 21, in new_func
    return f(get_current_context(), *args, **kwargs)
  File "/home/acer/environments/test2/lib/python3.6/site-packages/celery/bin/base.py", line 132, in caller
    return f(ctx, *args, **kwargs)
  File "/home/acer/environments/test2/lib/python3.6/site-packages/celery/bin/worker.py", line 326, in worker
    **kwargs)
  File "/home/acer/environments/test2/lib/python3.6/site-packages/celery/worker/worker.py", line 94, in __init__
    self.app.loader.init_worker()
  File "/home/acer/environments/test2/lib/python3.6/site-packages/celery/loaders/base.py", line 111, in init_worker
    self.import_default_modules()
  File "/home/acer/environments/test2/lib/python3.6/site-packages/celery/loaders/base.py", line 105, in import_default_modules
    raise response
  File "/home/acer/environments/test2/lib/python3.6/site-packages/celery/utils/dispatch/signal.py", line 276, in send
    response = receiver(signal=self, sender=sender, **named)
  File "/home/acer/environments/test2/lib/python3.6/site-packages/celery/fixups/django.py", line 82, in on_import_modules
    self.worker_fixup.validate_models()
  File "/home/acer/environments/test2/lib/python3.6/site-packages/celery/fixups/django.py", line 121, in validate_models
    run_checks()
  File "/home/acer/environments/test2/lib/python3.6/site-packages/django/core/checks/registry.py", line 76, in run_checks
    new_errors = check(app_configs=app_configs, databases=databases)
  File "/home/acer/environments/test2/lib/python3.6/site-packages/django/core/checks/urls.py", line 13, in check_url_config
    return check_resolver(resolver)
  File "/home/acer/environments/test2/lib/python3.6/site-packages/django/core/checks/urls.py", line 23, in check_resolver
    return check_method()
  File "/home/acer/environments/test2/lib/python3.6/site-packages/django/urls/resolvers.py", line 412, in check
    for pattern in self.url_patterns:
  File "/home/acer/environments/test2/lib/python3.6/site-packages/django/utils/functional.py", line 48, in __get__
    res = instance.__dict__[self.name] = self.func(instance)
  File "/home/acer/environments/test2/lib/python3.6/site-packages/django/urls/resolvers.py", line 598, in url_patterns
    patterns = getattr(self.urlconf_module, "urlpatterns", self.urlconf_module)
  File "/home/acer/environments/test2/lib/python3.6/site-packages/django/utils/functional.py", line 48, in __get__
    res = instance.__dict__[self.name] = self.func(instance)
  File "/home/acer/environments/test2/lib/python3.6/site-packages/django/urls/resolvers.py", line 591, in urlconf_module
    return import_module(self.urlconf_name)
  File "/usr/lib/python3.6/importlib/__init__.py", line 126, in import_module
    return _bootstrap._gcd_import(name[level:], package, level)
  File "<frozen importlib._bootstrap>", line 994, in _gcd_import
  File "<frozen importlib._bootstrap>", line 971, in _find_and_load
  File "<frozen importlib._bootstrap>", line 955, in _find_and_load_unlocked
  File "<frozen importlib._bootstrap>", line 665, in _load_unlocked
  File "<frozen importlib._bootstrap_external>", line 678, in exec_module
  File "<frozen importlib._bootstrap>", line 219, in _call_with_frames_removed
  File "/home/acer/projects/tracker/tracker/urls.py", line 24, in <module>
    path('core/', include('core.urls')),
  File "/home/acer/environments/test2/lib/python3.6/site-packages/django/urls/conf.py", line 34, in include
    urlconf_module = import_module(urlconf_module)
  File "/usr/lib/python3.6/importlib/__init__.py", line 126, in import_module
    return _bootstrap._gcd_import(name[level:], package, level)
  File "<frozen importlib._bootstrap>", line 994, in _gcd_import
  File "<frozen importlib._bootstrap>", line 971, in _find_and_load
  File "<frozen importlib._bootstrap>", line 955, in _find_and_load_unlocked
  File "<frozen importlib._bootstrap>", line 665, in _load_unlocked
  File "<frozen importlib._bootstrap_external>", line 678, in exec_module
  File "<frozen importlib._bootstrap>", line 219, in _call_with_frames_removed
  File "/home/acer/projects/tracker/core/urls.py", line 2, in <module>
    from core import views
  File "/home/acer/projects/tracker/core/views.py", line 14, in <module>
    from core.tasks import send_email
  File "/home/acer/projects/tracker/core/tasks.py", line 9
    send_mail(obj.id, constants.UPDATE_MESSAGE, settings.EMAIL_HOST_USER, to_users)
                                                                                  ^
TabError: inconsistent use of tabs and spaces in indentation
/home/beibarys/development/tracker/venv/lib/python3.7/site-packages/celery/platforms.py:797: RuntimeWarning: You're running the worker with superuser privileges: this is
absolutely not recommended!

Please specify a different user using the --uid option.

User information: uid=0 euid=0 gid=0 egid=0

  uid=uid, euid=euid, gid=gid, egid=egid,
[2021-05-04 10:11:37,372: INFO/MainProcess] Connected to amqp://myuser:**@127.0.0.1:5672/myvhost
[2021-05-04 10:11:37,382: INFO/MainProcess] mingle: searching for neighbors
[2021-05-04 10:11:38,410: INFO/MainProcess] mingle: all alone
[2021-05-04 10:11:38,444: WARNING/MainProcess] /home/beibarys/development/tracker/venv/lib/python3.7/site-packages/celery/fixups/django.py:204: UserWarning: Using settings.DEBUG leads to a memory
            leak, never use this setting in production environments!
  leak, never use this setting in production environments!''')

[2021-05-04 10:11:38,444: INFO/MainProcess] celery@beibarys ready.
[2021-05-04 11:01:05,192: INFO/MainProcess] Received task: core.tasks.send_email[40a09b9f-e4f4-46c7-917b-563f704c0c11]  
/home/beibarys/development/tracker/venv/lib/python3.7/site-packages/celery/platforms.py:797: RuntimeWarning: You're running the worker with superuser privileges: this is
absolutely not recommended!

Please specify a different user using the --uid option.

User information: uid=0 euid=0 gid=0 egid=0

  uid=uid, euid=euid, gid=gid, egid=egid,
[2021-05-04 11:01:05,207: ERROR/ForkPoolWorker-8] Task core.tasks.send_email[40a09b9f-e4f4-46c7-917b-563f704c0c11] raised unexpected: TypeError("send_email() got an unexpected keyword argument 'pk'")
Traceback (most recent call last):
  File "/home/beibarys/development/tracker/venv/lib/python3.7/site-packages/celery/app/trace.py", line 405, in trace_task
    R = retval = fun(*args, **kwargs)
  File "/home/beibarys/development/tracker/venv/lib/python3.7/site-packages/celery/app/trace.py", line 697, in __protected_call__
    return self.run(*args, **kwargs)
TypeError: send_email() got an unexpected keyword argument 'pk'
[2021-05-04 11:23:51,026: ERROR/MainProcess] Received unregistered task of type 'tracker.tasks.my_task'.
The message has been ignored and discarded.

Did you remember to import the module containing this task?
Or maybe you're using relative imports?

Please see
http://docs.celeryq.org/en/latest/internals/protocol.html
for more information.

The full contents of the message body was:
'[[], {}, {"callbacks": null, "errbacks": null, "chain": null, "chord": null}]' (77b)
Traceback (most recent call last):
  File "/home/beibarys/development/tracker/venv/lib/python3.7/site-packages/celery/worker/consumer/consumer.py", line 555, in on_task_received
    strategy = strategies[type_]
KeyError: 'tracker.tasks.my_task'
[2021-05-04 11:24:00,976: ERROR/MainProcess] Received unregistered task of type 'tracker.tasks.my_task'.
The message has been ignored and discarded.

Did you remember to import the module containing this task?
Or maybe you're using relative imports?

Please see
http://docs.celeryq.org/en/latest/internals/protocol.html
for more information.

The full contents of the message body was:
'[[], {}, {"callbacks": null, "errbacks": null, "chain": null, "chord": null}]' (77b)
Traceback (most recent call last):
  File "/home/beibarys/development/tracker/venv/lib/python3.7/site-packages/celery/worker/consumer/consumer.py", line 555, in on_task_received
    strategy = strategies[type_]
KeyError: 'tracker.tasks.my_task'
[2021-05-04 11:24:10,977: ERROR/MainProcess] Received unregistered task of type 'tracker.tasks.my_task'.
The message has been ignored and discarded.

Did you remember to import the module containing this task?
Or maybe you're using relative imports?

Please see
http://docs.celeryq.org/en/latest/internals/protocol.html
for more information.

The full contents of the message body was:
'[[], {}, {"callbacks": null, "errbacks": null, "chain": null, "chord": null}]' (77b)
Traceback (most recent call last):
  File "/home/beibarys/development/tracker/venv/lib/python3.7/site-packages/celery/worker/consumer/consumer.py", line 555, in on_task_received
    strategy = strategies[type_]
KeyError: 'tracker.tasks.my_task'
[2021-05-04 11:24:20,977: ERROR/MainProcess] Received unregistered task of type 'tracker.tasks.my_task'.
The message has been ignored and discarded.

Did you remember to import the module containing this task?
Or maybe you're using relative imports?

Please see
http://docs.celeryq.org/en/latest/internals/protocol.html
for more information.

The full contents of the message body was:
'[[], {}, {"callbacks": null, "errbacks": null, "chain": null, "chord": null}]' (77b)
Traceback (most recent call last):
  File "/home/beibarys/development/tracker/venv/lib/python3.7/site-packages/celery/worker/consumer/consumer.py", line 555, in on_task_received
    strategy = strategies[type_]
KeyError: 'tracker.tasks.my_task'
[2021-05-04 11:24:30,974: ERROR/MainProcess] Received unregistered task of type 'tracker.tasks.my_task'.
The message has been ignored and discarded.

Did you remember to import the module containing this task?
Or maybe you're using relative imports?

Please see
http://docs.celeryq.org/en/latest/internals/protocol.html
for more information.

The full contents of the message body was:
'[[], {}, {"callbacks": null, "errbacks": null, "chain": null, "chord": null}]' (77b)
Traceback (most recent call last):
  File "/home/beibarys/development/tracker/venv/lib/python3.7/site-packages/celery/worker/consumer/consumer.py", line 555, in on_task_received
    strategy = strategies[type_]
KeyError: 'tracker.tasks.my_task'
[2021-05-04 11:24:40,977: ERROR/MainProcess] Received unregistered task of type 'tracker.tasks.my_task'.
The message has been ignored and discarded.

Did you remember to import the module containing this task?
Or maybe you're using relative imports?

Please see
http://docs.celeryq.org/en/latest/internals/protocol.html
for more information.

The full contents of the message body was:
'[[], {}, {"callbacks": null, "errbacks": null, "chain": null, "chord": null}]' (77b)
Traceback (most recent call last):
  File "/home/beibarys/development/tracker/venv/lib/python3.7/site-packages/celery/worker/consumer/consumer.py", line 555, in on_task_received
    strategy = strategies[type_]
KeyError: 'tracker.tasks.my_task'
[2021-05-04 11:24:50,978: ERROR/MainProcess] Received unregistered task of type 'tracker.tasks.my_task'.
The message has been ignored and discarded.

Did you remember to import the module containing this task?
Or maybe you're using relative imports?

Please see
http://docs.celeryq.org/en/latest/internals/protocol.html
for more information.

The full contents of the message body was:
'[[], {}, {"callbacks": null, "errbacks": null, "chain": null, "chord": null}]' (77b)
Traceback (most recent call last):
  File "/home/beibarys/development/tracker/venv/lib/python3.7/site-packages/celery/worker/consumer/consumer.py", line 555, in on_task_received
    strategy = strategies[type_]
KeyError: 'tracker.tasks.my_task'
[2021-05-04 11:25:00,979: ERROR/MainProcess] Received unregistered task of type 'tracker.tasks.my_task'.
The message has been ignored and discarded.

Did you remember to import the module containing this task?
Or maybe you're using relative imports?

Please see
http://docs.celeryq.org/en/latest/internals/protocol.html
for more information.

The full contents of the message body was:
'[[], {}, {"callbacks": null, "errbacks": null, "chain": null, "chord": null}]' (77b)
Traceback (most recent call last):
  File "/home/beibarys/development/tracker/venv/lib/python3.7/site-packages/celery/worker/consumer/consumer.py", line 555, in on_task_received
    strategy = strategies[type_]
KeyError: 'tracker.tasks.my_task'
[2021-05-04 11:25:10,979: ERROR/MainProcess] Received unregistered task of type 'tracker.tasks.my_task'.
The message has been ignored and discarded.

Did you remember to import the module containing this task?
Or maybe you're using relative imports?

Please see
http://docs.celeryq.org/en/latest/internals/protocol.html
for more information.

The full contents of the message body was:
'[[], {}, {"callbacks": null, "errbacks": null, "chain": null, "chord": null}]' (77b)
Traceback (most recent call last):
  File "/home/beibarys/development/tracker/venv/lib/python3.7/site-packages/celery/worker/consumer/consumer.py", line 555, in on_task_received
    strategy = strategies[type_]
KeyError: 'tracker.tasks.my_task'
[2021-05-04 11:25:20,979: ERROR/MainProcess] Received unregistered task of type 'tracker.tasks.my_task'.
The message has been ignored and discarded.

Did you remember to import the module containing this task?
Or maybe you're using relative imports?

Please see
http://docs.celeryq.org/en/latest/internals/protocol.html
for more information.

The full contents of the message body was:
'[[], {}, {"callbacks": null, "errbacks": null, "chain": null, "chord": null}]' (77b)
Traceback (most recent call last):
  File "/home/beibarys/development/tracker/venv/lib/python3.7/site-packages/celery/worker/consumer/consumer.py", line 555, in on_task_received
    strategy = strategies[type_]
KeyError: 'tracker.tasks.my_task'
[2021-05-04 11:25:30,977: ERROR/MainProcess] Received unregistered task of type 'tracker.tasks.my_task'.
The message has been ignored and discarded.

Did you remember to import the module containing this task?
Or maybe you're using relative imports?

Please see
http://docs.celeryq.org/en/latest/internals/protocol.html
for more information.

The full contents of the message body was:
'[[], {}, {"callbacks": null, "errbacks": null, "chain": null, "chord": null}]' (77b)
Traceback (most recent call last):
  File "/home/beibarys/development/tracker/venv/lib/python3.7/site-packages/celery/worker/consumer/consumer.py", line 555, in on_task_received
    strategy = strategies[type_]
KeyError: 'tracker.tasks.my_task'
[2021-05-04 11:25:40,979: ERROR/MainProcess] Received unregistered task of type 'tracker.tasks.my_task'.
The message has been ignored and discarded.

Did you remember to import the module containing this task?
Or maybe you're using relative imports?

Please see
http://docs.celeryq.org/en/latest/internals/protocol.html
for more information.

The full contents of the message body was:
'[[], {}, {"callbacks": null, "errbacks": null, "chain": null, "chord": null}]' (77b)
Traceback (most recent call last):
  File "/home/beibarys/development/tracker/venv/lib/python3.7/site-packages/celery/worker/consumer/consumer.py", line 555, in on_task_received
    strategy = strategies[type_]
KeyError: 'tracker.tasks.my_task'
[2021-05-04 11:25:50,979: ERROR/MainProcess] Received unregistered task of type 'tracker.tasks.my_task'.
The message has been ignored and discarded.

Did you remember to import the module containing this task?
Or maybe you're using relative imports?

Please see
http://docs.celeryq.org/en/latest/internals/protocol.html
for more information.

The full contents of the message body was:
'[[], {}, {"callbacks": null, "errbacks": null, "chain": null, "chord": null}]' (77b)
Traceback (most recent call last):
  File "/home/beibarys/development/tracker/venv/lib/python3.7/site-packages/celery/worker/consumer/consumer.py", line 555, in on_task_received
    strategy = strategies[type_]
KeyError: 'tracker.tasks.my_task'
[2021-05-04 11:26:00,980: ERROR/MainProcess] Received unregistered task of type 'tracker.tasks.my_task'.
The message has been ignored and discarded.

Did you remember to import the module containing this task?
Or maybe you're using relative imports?

Please see
http://docs.celeryq.org/en/latest/internals/protocol.html
for more information.

The full contents of the message body was:
'[[], {}, {"callbacks": null, "errbacks": null, "chain": null, "chord": null}]' (77b)
Traceback (most recent call last):
  File "/home/beibarys/development/tracker/venv/lib/python3.7/site-packages/celery/worker/consumer/consumer.py", line 555, in on_task_received
    strategy = strategies[type_]
KeyError: 'tracker.tasks.my_task'
[2021-05-04 11:26:10,981: ERROR/MainProcess] Received unregistered task of type 'tracker.tasks.my_task'.
The message has been ignored and discarded.

Did you remember to import the module containing this task?
Or maybe you're using relative imports?

Please see
http://docs.celeryq.org/en/latest/internals/protocol.html
for more information.

The full contents of the message body was:
'[[], {}, {"callbacks": null, "errbacks": null, "chain": null, "chord": null}]' (77b)
Traceback (most recent call last):
  File "/home/beibarys/development/tracker/venv/lib/python3.7/site-packages/celery/worker/consumer/consumer.py", line 555, in on_task_received
    strategy = strategies[type_]
KeyError: 'tracker.tasks.my_task'
[2021-05-04 11:26:20,978: ERROR/MainProcess] Received unregistered task of type 'tracker.tasks.my_task'.
The message has been ignored and discarded.

Did you remember to import the module containing this task?
Or maybe you're using relative imports?

Please see
http://docs.celeryq.org/en/latest/internals/protocol.html
for more information.

The full contents of the message body was:
'[[], {}, {"callbacks": null, "errbacks": null, "chain": null, "chord": null}]' (77b)
Traceback (most recent call last):
  File "/home/beibarys/development/tracker/venv/lib/python3.7/site-packages/celery/worker/consumer/consumer.py", line 555, in on_task_received
    strategy = strategies[type_]
KeyError: 'tracker.tasks.my_task'
[2021-05-04 11:26:30,981: ERROR/MainProcess] Received unregistered task of type 'tracker.tasks.my_task'.
The message has been ignored and discarded.

Did you remember to import the module containing this task?
Or maybe you're using relative imports?

Please see
http://docs.celeryq.org/en/latest/internals/protocol.html
for more information.

The full contents of the message body was:
'[[], {}, {"callbacks": null, "errbacks": null, "chain": null, "chord": null}]' (77b)
Traceback (most recent call last):
  File "/home/beibarys/development/tracker/venv/lib/python3.7/site-packages/celery/worker/consumer/consumer.py", line 555, in on_task_received
    strategy = strategies[type_]
KeyError: 'tracker.tasks.my_task'
[2021-05-04 11:26:40,981: ERROR/MainProcess] Received unregistered task of type 'tracker.tasks.my_task'.
The message has been ignored and discarded.

Did you remember to import the module containing this task?
Or maybe you're using relative imports?

Please see
http://docs.celeryq.org/en/latest/internals/protocol.html
for more information.

The full contents of the message body was:
'[[], {}, {"callbacks": null, "errbacks": null, "chain": null, "chord": null}]' (77b)
Traceback (most recent call last):
  File "/home/beibarys/development/tracker/venv/lib/python3.7/site-packages/celery/worker/consumer/consumer.py", line 555, in on_task_received
    strategy = strategies[type_]
KeyError: 'tracker.tasks.my_task'
[2021-05-04 11:26:50,979: ERROR/MainProcess] Received unregistered task of type 'tracker.tasks.my_task'.
The message has been ignored and discarded.

Did you remember to import the module containing this task?
Or maybe you're using relative imports?

Please see
http://docs.celeryq.org/en/latest/internals/protocol.html
for more information.

The full contents of the message body was:
'[[], {}, {"callbacks": null, "errbacks": null, "chain": null, "chord": null}]' (77b)
Traceback (most recent call last):
  File "/home/beibarys/development/tracker/venv/lib/python3.7/site-packages/celery/worker/consumer/consumer.py", line 555, in on_task_received
    strategy = strategies[type_]
KeyError: 'tracker.tasks.my_task'
[2021-05-04 11:27:00,981: ERROR/MainProcess] Received unregistered task of type 'tracker.tasks.my_task'.
The message has been ignored and discarded.

Did you remember to import the module containing this task?
Or maybe you're using relative imports?

Please see
http://docs.celeryq.org/en/latest/internals/protocol.html
for more information.

The full contents of the message body was:
'[[], {}, {"callbacks": null, "errbacks": null, "chain": null, "chord": null}]' (77b)
Traceback (most recent call last):
  File "/home/beibarys/development/tracker/venv/lib/python3.7/site-packages/celery/worker/consumer/consumer.py", line 555, in on_task_received
    strategy = strategies[type_]
KeyError: 'tracker.tasks.my_task'
[2021-05-04 11:27:10,979: ERROR/MainProcess] Received unregistered task of type 'tracker.tasks.my_task'.
The message has been ignored and discarded.

Did you remember to import the module containing this task?
Or maybe you're using relative imports?

Please see
http://docs.celeryq.org/en/latest/internals/protocol.html
for more information.

The full contents of the message body was:
'[[], {}, {"callbacks": null, "errbacks": null, "chain": null, "chord": null}]' (77b)
Traceback (most recent call last):
  File "/home/beibarys/development/tracker/venv/lib/python3.7/site-packages/celery/worker/consumer/consumer.py", line 555, in on_task_received
    strategy = strategies[type_]
KeyError: 'tracker.tasks.my_task'
[2021-05-04 11:31:48,709: ERROR/MainProcess] Received unregistered task of type 'tracker.tasks.my_task'.
The message has been ignored and discarded.

Did you remember to import the module containing this task?
Or maybe you're using relative imports?

Please see
http://docs.celeryq.org/en/latest/internals/protocol.html
for more information.

The full contents of the message body was:
'[[], {}, {"callbacks": null, "errbacks": null, "chain": null, "chord": null}]' (77b)
Traceback (most recent call last):
  File "/home/beibarys/development/tracker/venv/lib/python3.7/site-packages/celery/worker/consumer/consumer.py", line 555, in on_task_received
    strategy = strategies[type_]
KeyError: 'tracker.tasks.my_task'
[2021-05-04 11:31:58,693: ERROR/MainProcess] Received unregistered task of type 'tracker.tasks.my_task'.
The message has been ignored and discarded.

Did you remember to import the module containing this task?
Or maybe you're using relative imports?

Please see
http://docs.celeryq.org/en/latest/internals/protocol.html
for more information.

The full contents of the message body was:
'[[], {}, {"callbacks": null, "errbacks": null, "chain": null, "chord": null}]' (77b)
Traceback (most recent call last):
  File "/home/beibarys/development/tracker/venv/lib/python3.7/site-packages/celery/worker/consumer/consumer.py", line 555, in on_task_received
    strategy = strategies[type_]
KeyError: 'tracker.tasks.my_task'
[2021-05-04 11:32:08,693: ERROR/MainProcess] Received unregistered task of type 'tracker.tasks.my_task'.
The message has been ignored and discarded.

Did you remember to import the module containing this task?
Or maybe you're using relative imports?

Please see
http://docs.celeryq.org/en/latest/internals/protocol.html
for more information.

The full contents of the message body was:
'[[], {}, {"callbacks": null, "errbacks": null, "chain": null, "chord": null}]' (77b)
Traceback (most recent call last):
  File "/home/beibarys/development/tracker/venv/lib/python3.7/site-packages/celery/worker/consumer/consumer.py", line 555, in on_task_received
    strategy = strategies[type_]
KeyError: 'tracker.tasks.my_task'
[2021-05-04 11:43:18,607: ERROR/MainProcess] Received unregistered task of type 'tracker.tasks.my_task'.
The message has been ignored and discarded.

Did you remember to import the module containing this task?
Or maybe you're using relative imports?

Please see
http://docs.celeryq.org/en/latest/internals/protocol.html
for more information.

The full contents of the message body was:
'[[], {}, {"callbacks": null, "errbacks": null, "chain": null, "chord": null}]' (77b)
Traceback (most recent call last):
  File "/home/beibarys/development/tracker/venv/lib/python3.7/site-packages/celery/worker/consumer/consumer.py", line 555, in on_task_received
    strategy = strategies[type_]
KeyError: 'tracker.tasks.my_task'
[2021-05-04 11:44:00,008: ERROR/MainProcess] Received unregistered task of type 'tracker.tasks.my_task'.
The message has been ignored and discarded.

Did you remember to import the module containing this task?
Or maybe you're using relative imports?

Please see
http://docs.celeryq.org/en/latest/internals/protocol.html
for more information.

The full contents of the message body was:
'[[], {}, {"callbacks": null, "errbacks": null, "chain": null, "chord": null}]' (77b)
Traceback (most recent call last):
  File "/home/beibarys/development/tracker/venv/lib/python3.7/site-packages/celery/worker/consumer/consumer.py", line 555, in on_task_received
    strategy = strategies[type_]
KeyError: 'tracker.tasks.my_task'
[2021-05-04 11:45:00,053: ERROR/MainProcess] Received unregistered task of type 'tracker.tasks.my_task'.
The message has been ignored and discarded.

Did you remember to import the module containing this task?
Or maybe you're using relative imports?

Please see
http://docs.celeryq.org/en/latest/internals/protocol.html
for more information.

The full contents of the message body was:
'[[], {}, {"callbacks": null, "errbacks": null, "chain": null, "chord": null}]' (77b)
Traceback (most recent call last):
  File "/home/beibarys/development/tracker/venv/lib/python3.7/site-packages/celery/worker/consumer/consumer.py", line 555, in on_task_received
    strategy = strategies[type_]
KeyError: 'tracker.tasks.my_task'
[2021-05-04 11:45:10,925: INFO/MainProcess] Received task: core.tasks.send_email[d2fd3983-a215-407f-b7be-c933aff8f8db]  
[2021-05-04 11:45:10,927: ERROR/ForkPoolWorker-8] Task core.tasks.send_email[d2fd3983-a215-407f-b7be-c933aff8f8db] raised unexpected: TypeError("send_email() got an unexpected keyword argument 'pk'")
Traceback (most recent call last):
  File "/home/beibarys/development/tracker/venv/lib/python3.7/site-packages/celery/app/trace.py", line 405, in trace_task
    R = retval = fun(*args, **kwargs)
  File "/home/beibarys/development/tracker/venv/lib/python3.7/site-packages/celery/app/trace.py", line 697, in __protected_call__
    return self.run(*args, **kwargs)
TypeError: send_email() got an unexpected keyword argument 'pk'
[2021-05-04 11:46:00,051: ERROR/MainProcess] Received unregistered task of type 'tracker.tasks.my_task'.
The message has been ignored and discarded.

Did you remember to import the module containing this task?
Or maybe you're using relative imports?

Please see
http://docs.celeryq.org/en/latest/internals/protocol.html
for more information.

The full contents of the message body was:
'[[], {}, {"callbacks": null, "errbacks": null, "chain": null, "chord": null}]' (77b)
Traceback (most recent call last):
  File "/home/beibarys/development/tracker/venv/lib/python3.7/site-packages/celery/worker/consumer/consumer.py", line 555, in on_task_received
    strategy = strategies[type_]
KeyError: 'tracker.tasks.my_task'
[2021-05-04 11:47:48,510: INFO/MainProcess] Events of group {task} enabled by remote.
[2021-05-04 11:48:29,440: INFO/MainProcess] Received task: core.tasks.send_email[df16d7a8-86d1-410f-bce4-e64a7c373c2b]  
[2021-05-04 11:48:29,442: ERROR/ForkPoolWorker-8] Task core.tasks.send_email[df16d7a8-86d1-410f-bce4-e64a7c373c2b] raised unexpected: TypeError("send_email() got an unexpected keyword argument 'pk'")
Traceback (most recent call last):
  File "/home/beibarys/development/tracker/venv/lib/python3.7/site-packages/celery/app/trace.py", line 405, in trace_task
    store_result(
  File "/home/beibarys/development/tracker/venv/lib/python3.7/site-packages/celery/app/trace.py", line 697, in __protected_call__
TypeError: send_email() got an unexpected keyword argument 'pk'
